Traceback (most recent call last):
  File "C:\Users\user\AppData\Local\Programs\Python\Python38\lib\runpy.py", line 194, in _run_module_as_main
    return _run_code(code, main_globals, None,
  File "C:\Users\user\AppData\Local\Programs\Python\Python38\lib\runpy.py", line 87, in _run_code
    exec(code, run_globals)
  File "C:\Users\user\Documents\My Documents\Git Experiments\assemblies\simulations\assemblies_merge.py", line 100, in <module>
    assembly3 = (assembly1 + assembly2) >> area3
  File "C:\Users\user\Documents\My Documents\Git Experiments\assemblies\assembly_calculus\assemblies\assembly.py", line 90, in __rshift__
    return self.merge(target_area)
  File "C:\Users\user\Documents\My Documents\Git Experiments\assemblies\utils\blueprints\recordable.py", line 66, in wrapper
    return function(*args, **kwargs)
  File "C:\Users\user\Documents\My Documents\Git Experiments\assemblies\assembly_calculus\assemblies\assembly.py", line 67, in merge
    return Assembly._merge(self.assemblies, area, brain=brain)
  File "C:\Users\user\Documents\My Documents\Git Experiments\assemblies\assembly_calculus\assemblies\assembly.py", line 247, in _merge
    merged_assembly: Assembly = Assembly(assemblies, area,
  File "C:\Users\user\Documents\My Documents\Git Experiments\assemblies\utils\bindable.py", line 90, in new_init
    original_init(self, *args, **kwargs)
  File "C:\Users\user\Documents\My Documents\Git Experiments\assemblies\utils\bindable.py", line 90, in new_init
    original_init(self, *args, **kwargs)
TypeError: __init__() got an unexpected keyword argument 'appears_in'
